<!--waist link -> shoulderA link -> shoulderB link -> elbow link -> wristA link -> wristB link-->

<robot name="ArmBot">

	<!--Links-->

	
	<link name="waistLink">
		<visual>
			<origin xyz="0 0 0" rpy="0 0 0"/>
			<geometry>
				<cylinder length="0.05" radius="0.1"/>
			</geometry>
		</visual>
	</link>

	<link name="shoulderALink">
		<visual>
			<origin xyz="0 0 0.381" rpy="0 0 0"/>
			<geometry>
				<box size="0.05 0.05 0.05"/>
			</geometry>
		</visual>
	</link>

	<link name="shoulderBLink">
		<visual>
			<origin xyz="0 0 0" rpy="0 0 0"/>
			<geometry>
				<box size="0.05 0.05 0.05"/>
			</geometry>
		</visual>
	</link>

	<link name="elbowLink">
		<visual>
			<origin xyz="0 0.3048 0" rpy="0 0 0"/>
			<geometry>
				<box size="0.05 0.05 0.05"/>
			</geometry>
		</visual>
	</link>

	<link name="wristALink">
		<visual>
			<origin xyz="0 0.3048 0" rpy="0 0 0"/>
			<geometry>
				<box size="0.05 0.05 0.05"/>
			</geometry>
		</visual>
	</link>
	
	<link name="wristBLink">
		<visual>
			<origin xyz="0 0 0" rpy="1.57 0 0"/>
			<geometry>
				<cylinder length="0.1" radius="0.01"/>
			</geometry>
		</visual>
	</link>


	<!--Joints-->


	<joint name="waistJoint" type="revolute">
		<parent link="waistLink"/>
		<child link="shoulderALink"/>
		<origin xyz="0 0 0" rpy="0 0 0"/>
		<limit lower="-6.29" upper="6.29" effort="10" velocity="4"/>
		<axis xyz="0 0 1"/>
	</joint>

	<joint name="shoulderAJoint" type="revolute">
		<parent link="shoulderALink"/>
		<child link="shoulderBLink"/>
		<origin xyz="0 0 0.381" rpy="0 0 0"/>
		<limit lower="-3.1416" upper="3.1416" effort="10" velocity="4"/>
		<axis xyz="0 1 0"/>
	</joint>

	<joint name="shoulderBJoint" type="revolute">
		<parent link="shoulderBLink"/>
		<child link="elbowLink"/>
		<origin xyz="0 0 0" rpy="0 0 0"/>
		<limit lower="-1.308" upper="1.308" effort="10" velocity="4"/>
		<axis xyz="0 0 1"/>
	</joint>

	<joint name="elbowJoint" type="revolute">
		<parent link="elbowLink"/>
		<child link="wristALink"/>
		<origin xyz="0 0.3048 0" rpy="0 0 0"/>
		<limit lower="-1.308" upper="1.308" effort="10" velocity="4"/>
		<axis xyz="0 0 1"/>
	</joint>

	<joint name="wristAJoint" type="revolute">
		<parent link="wristALink"/>
		<child link="wristBLink"/>
		<origin xyz="0 0.3048 0" rpy="0 0 0"/>
		<limit lower="-1.308" upper="1.308" effort="10" velocity="4"/>
		<axis xyz="0 0 1"/>
	</joint>

</robot>
